<mujoco>
  <compiler autolimits="true"/>
  
  <worldbody>
    <!-- Bottom humanoid 1 (Red) - positioned so shoulders touch -->
    <body name="bottom_shoulder_bot" pos="0 0 1">
      <freejoint name="bottom_shoulder_bot_root"/>
      <body name="bottom_shoulder_bot_torso" pos="0 0 0.282">
        <geom name="bottom_shoulder_bot_torso" fromto="0 -.07 0 0 .07 0" size=".07" type="capsule"/>
        <geom name="bottom_shoulder_bot_waist_upper" fromto="-.01 -.06 -.12 -.01 .06 -.12" size=".06" type="capsule"/>
        
        <!-- Head -->
        <body name="bottom_shoulder_bot_head" pos="0 0 .19">
          <geom name="bottom_shoulder_bot_head" type="sphere" size=".09"/>
        </body>
        
        <!-- Right Arm -->
        <body name="bottom_shoulder_bot_upper_arm_right" pos="0 -.17 .06">
          <joint name="bottom_shoulder_bot_shoulder1_right" type="hinge" axis="2 1 1" range="-85 60"/>
          <joint name="bottom_shoulder_bot_shoulder2_right" type="hinge" axis="0 -1 1" range="-85 60"/>
          <geom name="bottom_shoulder_bot_upper_arm_right" fromto="0 0 0 .16 -.16 -.16" size=".04" type="capsule"/>
          <body name="bottom_shoulder_bot_lower_arm_right" pos=".18 -.18 -.18">
            <joint name="bottom_shoulder_bot_elbow_right" type="hinge" axis="0 -1 1" range="-100 50"/>
            <geom name="bottom_shoulder_bot_lower_arm_right" fromto=".01 .01 .01 .17 .17 .17" size=".031" type="capsule"/>
            <body name="bottom_shoulder_bot_hand_right" pos=".18 .18 .18">
              <geom name="bottom_shoulder_bot_hand_right" type="sphere" size=".04"/>
            </body>
          </body>
        </body>
        
        <!-- Left Arm -->
        <body name="bottom_shoulder_bot_upper_arm_left" pos="0 .17 .06">
          <joint name="bottom_shoulder_bot_shoulder1_left" type="hinge" axis="-2 1 -1" range="-85 60"/>
          <joint name="bottom_shoulder_bot_shoulder2_left" type="hinge" axis="0 -1 -1" range="-85 60"/>
          <geom name="bottom_shoulder_bot_upper_arm_left" fromto="0 0 0 .16 .16 -.16" size=".04" type="capsule"/>
          <body name="bottom_shoulder_bot_lower_arm_left" pos=".18 .18 -.18">
            <joint name="bottom_shoulder_bot_elbow_left" type="hinge" axis="0 -1 -1" range="-100 50"/>
            <geom name="bottom_shoulder_bot_lower_arm_left" fromto=".01 -.01 .01 .17 -.17 .17" size=".031" type="capsule"/>
            <body name="bottom_shoulder_bot_hand_left" pos=".18 -.18 .18">
              <geom name="bottom_shoulder_bot_hand_left" type="sphere" size=".04"/>
            </body>
          </body>
        </body>
        
        <!-- Lower Body -->
        <body name="bottom_shoulder_bot_waist_lower" pos="-.01 0 -.26">
          <geom name="bottom_shoulder_bot_waist_lower" fromto="0 -.06 0 0 .06 0" size=".06" type="capsule"/>
          <joint name="bottom_shoulder_bot_abdomen_z" pos="0 0 .065" axis="0 0 1" range="-45 45"/>
          <joint name="bottom_shoulder_bot_abdomen_y" pos="0 0 .065" axis="0 1 0" range="-75 30"/>
          <body name="bottom_shoulder_bot_pelvis" pos="0 0 -.165">
            <joint name="bottom_shoulder_bot_abdomen_x" pos="0 0 .1" axis="1 0 0" range="-35 35"/>
            <geom name="bottom_shoulder_bot_butt" fromto="-.02 -.07 0 -.02 .07 0" size=".09" type="capsule"/>
            
            <!-- Right Leg -->
            <body name="bottom_shoulder_bot_thigh_right" pos="0 -.1 -.04">
              <joint name="bottom_shoulder_bot_hip_x_right" type="hinge" axis="1 0 0" range="-30 10"/>
              <joint name="bottom_shoulder_bot_hip_z_right" type="hinge" axis="0 0 1" range="-60 35"/>
              <joint name="bottom_shoulder_bot_hip_y_right" type="hinge" axis="0 1 0" range="-150 20"/>
              <geom name="bottom_shoulder_bot_thigh_right" fromto="0 0 0 0 .01 -.34" size=".06" type="capsule"/>
              <body name="bottom_shoulder_bot_shin_right" pos="0 .01 -.4">
                <joint name="bottom_shoulder_bot_knee_right" type="hinge" axis="0 -1 0" range="-160 2"/>
                <geom name="bottom_shoulder_bot_shin_right" fromto="0 0 0 0 0 -.3" size=".049" type="capsule"/>
                <body name="bottom_shoulder_bot_foot_right" pos="0 0 -.39">
                  <joint name="bottom_shoulder_bot_ankle_y_right" type="hinge" pos="0 0 .08" axis="0 1 0" range="-50 50"/>
                  <joint name="bottom_shoulder_bot_ankle_x_right" type="hinge" pos="0 0 .04" axis="1 0 .5" range="-50 50"/>
                  <geom name="bottom_shoulder_bot_foot1_right" fromto="-.07 -.01 0 .14 -.03 0" size=".027" type="capsule"/>
                  <geom name="bottom_shoulder_bot_foot2_right" fromto="-.07 .01 0 .14 .03 0" size=".027" type="capsule"/>
                </body>
              </body>
            </body>
            
            <!-- Left Leg -->
            <body name="bottom_shoulder_bot_thigh_left" pos="0 .1 -.04">
              <joint name="bottom_shoulder_bot_hip_x_left" type="hinge" axis="-1 0 0" range="-30 10"/>
              <joint name="bottom_shoulder_bot_hip_z_left" type="hinge" axis="0 0 -1" range="-60 35"/>
              <joint name="bottom_shoulder_bot_hip_y_left" type="hinge" axis="0 1 0" range="-150 20"/>
              <geom name="bottom_shoulder_bot_thigh_left" fromto="0 0 0 0 -.01 -.34" size=".06" type="capsule"/>
              <body name="bottom_shoulder_bot_shin_left" pos="0 -.01 -.4">
                <joint name="bottom_shoulder_bot_knee_left" type="hinge" axis="0 -1 0" range="-160 2"/>
                <geom name="bottom_shoulder_bot_shin_left" fromto="0 0 0 0 0 -.3" size=".049" type="capsule"/>
                <body name="bottom_shoulder_bot_foot_left" pos="0 0 -.39">
                  <joint name="bottom_shoulder_bot_ankle_y_left" type="hinge" pos="0 0 .08" axis="0 1 0" range="-50 50"/>
                  <joint name="bottom_shoulder_bot_ankle_x_left" type="hinge" pos="0 0 .04" axis="-1 0 -.5" range="-50 50"/>
                  <geom name="bottom_shoulder_bot_foot1_left" fromto="-.07 -.01 0 .14 -.03 0" size=".027" type="capsule"/>
                  <geom name="bottom_shoulder_bot_foot2_left" fromto="-.07 .01 0 .14 .03 0" size=".027" type="capsule"/>
                </body>
              </body>
            </body>
          </body>
        </body>
      </body>
    </body>

    <!-- top_shoulder_bot humanoid (Blue) - positioned centered above both base robots -->
    <body name="top_shoulder_bot" pos="0 0 2.4">
      <freejoint name="top_shoulder_bot_root"/>
      <body name="top_shoulder_bot_torso" pos="0 0 0.282">
        <geom name="top_shoulder_bot_torso" fromto="0 -.07 0 0 .07 0" size=".07" type="capsule"/>
        <geom name="top_shoulder_bot_waist_upper" fromto="-.01 -.06 -.12 -.01 .06 -.12" size=".06" type="capsule"/>
        
        <!-- Head -->
        <body name="top_shoulder_bot_head" pos="0 0 .19">
          <geom name="top_shoulder_bot_head" type="sphere" size=".09"/>
        </body>
        
        <!-- Arms -->
        <body name="top_shoulder_bot_upper_arm_right" pos="0 -.17 .06">
          <joint name="top_shoulder_bot_shoulder1_right" type="hinge" axis="2 1 1" range="-85 60"/>
          <joint name="top_shoulder_bot_shoulder2_right" type="hinge" axis="0 -1 1" range="-85 60"/>
          <geom name="top_shoulder_bot_upper_arm_right" fromto="0 0 0 .16 -.16 -.16" size=".04" type="capsule"/>
          <body name="top_shoulder_bot_lower_arm_right" pos=".18 -.18 -.18">
            <joint name="top_shoulder_bot_elbow_right" type="hinge" axis="0 -1 1" range="-100 50"/>
            <geom name="top_shoulder_bot_lower_arm_right" fromto=".01 .01 .01 .17 .17 .17" size=".031" type="capsule"/>
            <body name="top_shoulder_bot_hand_right" pos=".18 .18 .18">
              <geom name="top_shoulder_bot_hand_right" type="sphere" size=".04"/>
            </body>
          </body>
        </body>
        
        <body name="top_shoulder_bot_upper_arm_left" pos="0 .17 .06">
          <joint name="top_shoulder_bot_shoulder1_left" type="hinge" axis="-2 1 -1" range="-85 60"/>
          <joint name="top_shoulder_bot_shoulder2_left" type="hinge" axis="0 -1 -1" range="-85 60"/>
          <geom name="top_shoulder_bot_upper_arm_left" fromto="0 0 0 .16 .16 -.16" size=".04" type="capsule"/>
          <body name="top_shoulder_bot_lower_arm_left" pos=".18 .18 -.18">
            <joint name="top_shoulder_bot_elbow_left" type="hinge" axis="0 -1 -1" range="-100 50"/>
            <geom name="top_shoulder_bot_lower_arm_left" fromto=".01 -.01 .01 .17 -.17 .17" size=".031" type="capsule"/>
            <body name="top_shoulder_bot_hand_left" pos=".18 -.18 .18">
              <geom name="top_shoulder_bot_hand_left" type="sphere" size=".04"/>
            </body>
          </body>
        </body>
        
        <!-- Lower Body -->
        <body name="top_shoulder_bot_waist_lower" pos="-.01 0 -.26">
          <geom name="top_shoulder_bot_waist_lower" fromto="0 -.06 0 0 .06 0" size=".06" type="capsule"/>
          <joint name="top_shoulder_bot_abdomen_z" pos="0 0 .065" axis="0 0 1" range="-45 45"/>
          <joint name="top_shoulder_bot_abdomen_y" pos="0 0 .065" axis="0 1 0" range="-75 30"/>
          <body name="top_shoulder_bot_pelvis" pos="0 0 -.165">
            <joint name="top_shoulder_bot_abdomen_x" pos="0 0 .1" axis="1 0 0" range="-35 35"/>
            <geom name="top_shoulder_bot_butt" fromto="-.02 -.07 0 -.02 .07 0" size=".09" type="capsule"/>
            
            <!-- Right Leg -->
            <body name="top_shoulder_bot_thigh_right" pos="0 -.1 -.04">
              <joint name="top_shoulder_bot_hip_x_right" type="hinge" axis="1 0 0" range="-30 10"/>
              <joint name="top_shoulder_bot_hip_z_right" type="hinge" axis="0 0 1" range="-60 35"/>
              <joint name="top_shoulder_bot_hip_y_right" type="hinge" axis="0 1 0" range="-150 20"/>
              <geom name="top_shoulder_bot_thigh_right" fromto="0 0 0 0 .01 -.34" size=".06" type="capsule"/>
              <body name="top_shoulder_bot_shin_right" pos="0 .01 -.4">
                <joint name="top_shoulder_bot_knee_right" type="hinge" axis="0 -1 0" range="-160 2"/>
                <geom name="top_shoulder_bot_shin_right" fromto="0 0 0 0 0 -.3" size=".049" type="capsule"/>
                <body name="top_shoulder_bot_foot_right" pos="0 0 -.39">
                  <joint name="top_shoulder_bot_ankle_y_right" type="hinge" pos="0 0 .08" axis="0 1 0" range="-50 50"/>
                  <joint name="top_shoulder_bot_ankle_x_right" type="hinge" pos="0 0 .04" axis="1 0 .5" range="-50 50"/>
                  <geom name="top_shoulder_bot_foot1_right" fromto="-.07 -.01 0 .14 -.03 0" size=".027" type="capsule"/>
                  <geom name="top_shoulder_bot_foot2_right" fromto="-.07 .01 0 .14 .03 0" size=".027" type="capsule"/>
                </body>
              </body>
            </body>
            
            <!-- Left Leg -->
            <body name="top_shoulder_bot_thigh_left" pos="0 .1 -.04">
              <joint name="top_shoulder_bot_hip_x_left" type="hinge" axis="-1 0 0" range="-30 10"/>
              <joint name="top_shoulder_bot_hip_z_left" type="hinge" axis="0 0 -1" range="-60 35"/>
              <joint name="top_shoulder_bot_hip_y_left" type="hinge" axis="0 1 0" range="-150 20"/>
              <geom name="top_shoulder_bot_thigh_left" fromto="0 0 0 0 -.01 -.34" size=".06" type="capsule"/>
              <body name="top_shoulder_bot_shin_left" pos="0 -.01 -.4">
                <joint name="top_shoulder_bot_knee_left" type="hinge" axis="0 -1 0" range="-160 2"/>
                <geom name="top_shoulder_bot_shin_left" fromto="0 0 0 0 0 -.3" size=".049" type="capsule"/>
                <body name="top_shoulder_bot_foot_left" pos="0 0 -.39">
                  <joint name="top_shoulder_bot_ankle_y_left" type="hinge" pos="0 0 .08" axis="0 1 0" range="-50 50"/>
                  <joint name="top_shoulder_bot_ankle_x_left" type="hinge" pos="0 0 .04" axis="-1 0 -.5" range="-50 50"/>
                  <geom name="top_shoulder_bot_foot1_left" fromto="-.07 -.01 0 .14 -.03 0" size=".027" type="capsule"/>
                  <geom name="top_shoulder_bot_foot2_left" fromto="-.07 .01 0 .14 .03 0" size=".027" type="capsule"/>
                </body>
              </body>
            </body>
          </body>
        </body>
      </body>
    </body>
  </worldbody>

  <equality>
    <!-- Weld top_shoulder_bot robot's feet to base robots' shoulders -->
    <weld name="weld_top_shoulder_bot_right" body1="top_shoulder_bot_foot_right" body2="bottom_shoulder_bot_upper_arm_right"
          anchor="0 0 0" solref="0.01 1" solimp="0.9 0.95 0.001"/>
    <weld name="weld_top_shoulder_bot_left" body1="top_shoulder_bot_foot_left" body2="bottom_shoulder_bot_upper_arm_left"
          anchor="0 0 0" solref="0.01 1" solimp="0.9 0.95 0.001"/>
  </equality>

  <!-- COMPLETE ACTUATORS FOR ALL JOINTS -->
  <actuator>
    <!-- Base Humanoid 1 (Red) Actuators -->
    <position name="bottom_shoulder_bot_abdomen_y" joint="bottom_shoulder_bot_abdomen_y" kp="100"/>
    <position name="bottom_shoulder_bot_abdomen_z" joint="bottom_shoulder_bot_abdomen_z" kp="100"/>
    <position name="bottom_shoulder_bot_abdomen_x" joint="bottom_shoulder_bot_abdomen_x" kp="100"/>
    <position name="bottom_shoulder_bot_hip_x_right" joint="bottom_shoulder_bot_hip_x_right" kp="100"/>
    <position name="bottom_shoulder_bot_hip_z_right" joint="bottom_shoulder_bot_hip_z_right" kp="100"/>
    <position name="bottom_shoulder_bot_hip_y_right" joint="bottom_shoulder_bot_hip_y_right" kp="100"/>
    <position name="bottom_shoulder_bot_knee_right" joint="bottom_shoulder_bot_knee_right" kp="80"/>
    <position name="bottom_shoulder_bot_ankle_x_right" joint="bottom_shoulder_bot_ankle_x_right" kp="50"/>
    <position name="bottom_shoulder_bot_ankle_y_right" joint="bottom_shoulder_bot_ankle_y_right" kp="50"/>
    <position name="bottom_shoulder_bot_hip_x_left" joint="bottom_shoulder_bot_hip_x_left" kp="100"/>
    <position name="bottom_shoulder_bot_hip_z_left" joint="bottom_shoulder_bot_hip_z_left" kp="100"/>
    <position name="bottom_shoulder_bot_hip_y_left" joint="bottom_shoulder_bot_hip_y_left" kp="100"/>
    <position name="bottom_shoulder_bot_knee_left" joint="bottom_shoulder_bot_knee_left" kp="80"/>
    <position name="bottom_shoulder_bot_ankle_x_left" joint="bottom_shoulder_bot_ankle_x_left" kp="50"/>
    <position name="bottom_shoulder_bot_ankle_y_left" joint="bottom_shoulder_bot_ankle_y_left" kp="50"/>
    <position name="bottom_shoulder_bot_shoulder1_right" joint="bottom_shoulder_bot_shoulder1_right" kp="50"/>
    <position name="bottom_shoulder_bot_shoulder2_right" joint="bottom_shoulder_bot_shoulder2_right" kp="50"/>
    <position name="bottom_shoulder_bot_elbow_right" joint="bottom_shoulder_bot_elbow_right" kp="50"/>
    <position name="bottom_shoulder_bot_shoulder1_left" joint="bottom_shoulder_bot_shoulder1_left" kp="50"/>
    <position name="bottom_shoulder_bot_shoulder2_left" joint="bottom_shoulder_bot_shoulder2_left" kp="50"/>
    <position name="bottom_shoulder_bot_elbow_left" joint="bottom_shoulder_bot_elbow_left" kp="50"/>

    <!-- top_shoulder_bot Humanoid (Blue) Actuators -->
    <position name="top_shoulder_bot_abdomen_y" joint="top_shoulder_bot_abdomen_y" kp="100"/>
    <position name="top_shoulder_bot_abdomen_z" joint="top_shoulder_bot_abdomen_z" kp="100"/>
    <position name="top_shoulder_bot_abdomen_x" joint="top_shoulder_bot_abdomen_x" kp="100"/>
    <position name="top_shoulder_bot_hip_x_right" joint="top_shoulder_bot_hip_x_right" kp="100"/>
    <position name="top_shoulder_bot_hip_z_right" joint="top_shoulder_bot_hip_z_right" kp="100"/>
    <position name="top_shoulder_bot_hip_y_right" joint="top_shoulder_bot_hip_y_right" kp="100"/>
    <position name="top_shoulder_bot_knee_right" joint="top_shoulder_bot_knee_right" kp="80"/>
    <position name="top_shoulder_bot_ankle_x_right" joint="top_shoulder_bot_ankle_x_right" kp="50"/>
    <position name="top_shoulder_bot_ankle_y_right" joint="top_shoulder_bot_ankle_y_right" kp="50"/>
    <position name="top_shoulder_bot_hip_x_left" joint="top_shoulder_bot_hip_x_left" kp="100"/>
    <position name="top_shoulder_bot_hip_z_left" joint="top_shoulder_bot_hip_z_left" kp="100"/>
    <position name="top_shoulder_bot_hip_y_left" joint="top_shoulder_bot_hip_y_left" kp="100"/>
    <position name="top_shoulder_bot_knee_left" joint="top_shoulder_bot_knee_left" kp="80"/>
    <position name="top_shoulder_bot_ankle_x_left" joint="top_shoulder_bot_ankle_x_left" kp="50"/>
    <position name="top_shoulder_bot_ankle_y_left" joint="top_shoulder_bot_ankle_y_left" kp="50"/>
    <position name="top_shoulder_bot_shoulder1_right" joint="top_shoulder_bot_shoulder1_right" kp="50"/>
    <position name="top_shoulder_bot_shoulder2_right" joint="top_shoulder_bot_shoulder2_right" kp="50"/>
    <position name="top_shoulder_bot_elbow_right" joint="top_shoulder_bot_elbow_right" kp="50"/>
    <position name="top_shoulder_bot_shoulder1_left" joint="top_shoulder_bot_shoulder1_left" kp="50"/>
    <position name="top_shoulder_bot_shoulder2_left" joint="top_shoulder_bot_shoulder2_left" kp="50"/>
    <position name="top_shoulder_bot_elbow_left" joint="top_shoulder_bot_elbow_left" kp="50"/>
  </actuator>
</mujoco>