<!-- Copyright 2021 DeepMind Technologies Limited

     Licensed under the Apache License, Version 2.0 (the "License");
     you may not use this file except in compliance with the License.
     You may obtain a copy of the License at

         http://www.apache.org/licenses/LICENSE-2.0

     Unless required by applicable law or agreed to in writing, software
     distributed under the License is distributed on an "AS IS" BASIS,
     WITHOUT WARRANTIES OR CONDITIONS OF ANY KIND, either express or implied.
     See the License for the specific language governing permissions and
     limitations under the License.
-->

<mujoco model="HumanoidBrace">
  <option timestep="0.005"/>

  <visual>
    <map force="0.1" zfar="30"/>
    <rgba haze="0.15 0.25 0.35 1"/>
    <global offwidth="2560" offheight="1440" elevation="-20" azimuth="120"/>
  </visual>

  <statistic center="0 0 0.7"/>

  <asset>
    <texture type="skybox" builtin="gradient" rgb1=".3 .5 .7" rgb2="0 0 0" width="32" height="512"/>
    <texture name="body" type="cube" builtin="flat" mark="cross" width="127" height="1278" rgb1="0.8 0.6 0.4" rgb2="0.8 0.6 0.4" markrgb="1 1 1" random="0.01"/>
    <material name="body" texture="body" texuniform="true" rgba="0.8 0.6 .4 1"/>
    <texture name="grid" type="2d" builtin="checker" width="512" height="512" rgb1="0 0 0" rgb2=".3 .3 .3"/>
    <material name="grid" texture="grid" texrepeat="1 1" texuniform="true" reflectance="0"/>
    <texture name="pointer" type="2d" builtin="checker" width="512" height="512" rgb1=".1 .2 .3" rgb2=".2 .3 .4"/>
    <material name="pointer" texture="pointer" texuniform="true" rgba="0.1 0 0 1"/>
    <material name="connector" rgba="0.3 0.3 0.8 0.7"/>
  </asset>

  <default>
    <motor ctrlrange="-1 1" ctrllimited="true"/>
    <default class="body">
      <!-- geoms -->
      <geom type="capsule" condim="1" friction=".7" solimp=".9 .99 .003" solref=".015 1" material="body"/>
      <default class="thigh">
        <geom size=".06"/>
      </default>
      <default class="shin">
        <geom fromto="0 0 0 0 0 -.3"  size=".049"/>
      </default>
      <default class="foot">
        <geom size=".027"/>
        <default class="foot1">
          <geom fromto="-.07 -.01 0 .14 -.03 0"/>
        </default>
        <default class="foot2">
          <geom fromto="-.07 .01 0 .14  .03 0"/>
        </default>
      </default>
      <default class="arm_upper">
        <geom size=".04"/>
      </default>
      <default class="arm_lower">
        <geom size=".031"/>
      </default>
      <default class="hand">
        <geom type="sphere" size=".04"/>
      </default>

      <!-- joints -->
      <joint type="hinge" damping=".2" stiffness="1" armature=".01" limited="true" solimplimit="0 .99 .01"/>
      <default class="joint_big">
        <joint damping="5" stiffness="10"/>
        <default class="hip_x">
          <joint range="-30 10"/>
        </default>
        <default class="hip_z">
          <joint range="-60 35"/>
        </default>
        <default class="hip_y">
          <joint axis="0 1 0" range="-150 20"/>
        </default>
        <default class="joint_big_stiff">
          <joint stiffness="20"/>
        </default>
      </default>
      <default class="knee">
        <joint pos="0 0 .02" axis="0 -1 0" range="-160 2"/>
      </default>
      <default class="ankle">
        <joint range="-50 50"/>
        <default class="ankle_y">
          <joint pos="0 0 .08" axis="0 1 0" stiffness="6"/>
        </default>
        <default class="ankle_x">
          <joint pos="0 0 .04" stiffness="3"/>
        </default>
      </default>
      <default class="shoulder">
        <joint range="-85 60"/>
      </default>
      <default class="elbow">
        <joint range="-100 50" stiffness="0"/>
      </default>
    </default>
  </default>

  <worldbody>
    <geom name="floor" size="0 0 .05" type="plane" material="grid" condim="3"/>
    <!-- Fixed spotlight - removed targetbodycom mode -->
    <light name="spotlight" diffuse=".8 .8 .8" specular="0.3 0.3 0.3" pos="0 -4 4" dir="0 1 0" directional="true"/>
    
    <!-- Humanoid 1 - North position -->
    <body name="humanoid1" pos="0 0.8 1.282" childclass="body">
      <freejoint name="root1"/>
      <geom name="torso1" fromto="0 -.07 0 0 .07 0" size=".07"/>
      <geom name="waist_upper1" fromto="-.01 -.06 -.12 -.01 .06 -.12" size=".06"/>
      <body name="head1" pos="0 0 .19">
        <geom name="head1" type="sphere" size=".09"/>
      </body>
      <body name="waist_lower1" pos="-.01 0 -.26">
        <geom name="waist_lower1" fromto="0 -.06 0 0 .06 0" size=".06"/>
        <joint name="abdomen_z1" pos="0 0 .065" axis="0 0 1" range="-45 45" class="joint_big_stiff"/>
        <joint name="abdomen_y1" pos="0 0 .065" axis="0 1 0" range="-75 30" class="joint_big"/>
        <body name="pelvis1" pos="0 0 -.165">
          <joint name="abdomen_x1" pos="0 0 .1" axis="1 0 0" range="-35 35" class="joint_big"/>
          <geom name="butt1" fromto="-.02 -.07 0 -.02 .07 0" size=".09"/>
          <!-- Legs for humanoid1 -->
          <body name="thigh_right1" pos="0 -.1 -.04">
            <joint name="hip_x_right1" axis="1 0 0" class="hip_x"/>
            <joint name="hip_z_right1" axis="0 0 1" class="hip_z"/>
            <joint name="hip_y_right1" class="hip_y"/>
            <geom name="thigh_right1" fromto="0 0 0 0 .01 -.34" class="thigh"/>
            <body name="shin_right1" pos="0 .01 -.4">
              <joint name="knee_right1" class="knee"/>
              <geom name="shin_right1" class="shin"/>
              <body name="foot_right1" pos="0 0 -.39">
                <joint name="ankle_y_right1" class="ankle_y"/>
                <joint name="ankle_x_right1" class="ankle_x" axis="1 0 .5"/>
                <geom name="foot1_right1" class="foot1"/>
                <geom name="foot2_right1" class="foot2"/>
              </body>
            </body>
          </body>
          <body name="thigh_left1" pos="0 .1 -.04">
            <joint name="hip_x_left1" axis="-1 0 0" class="hip_x"/>
            <joint name="hip_z_left1" axis="0 0 -1" class="hip_z"/>
            <joint name="hip_y_left1" class="hip_y"/>
            <geom name="thigh_left1" fromto="0 0 0 0 -.01 -.34" class="thigh"/>
            <body name="shin_left1" pos="0 -.01 -.4">
              <joint name="knee_left1" class="knee"/>
              <geom name="shin_left1" fromto="0 0 0 0 0 -.3" class="shin"/>
              <body name="foot_left1" pos="0 0 -.39">
                <joint name="ankle_y_left1" class="ankle_y"/>
                <joint name="ankle_x_left1" class="ankle_x" axis="-1 0 -.5"/>
                <geom name="foot1_left1" class="foot1"/>
                <geom name="foot2_left1" class="foot2"/>
              </body>
            </body>
          </body>
        </body>
      </body>
      <!-- Arms for humanoid1 -->
      <body name="upper_arm_right1" pos="0 -.17 .06">
        <joint name="shoulder1_right1" axis="2 1 1" class="shoulder"/>
        <joint name="shoulder2_right1" axis="0 -1 1" class="shoulder"/>
        <geom name="upper_arm_right1" fromto="0 0 0 .16 -.16 -.16" class="arm_upper"/>
        <body name="lower_arm_right1" pos=".18 -.18 -.18">
          <joint name="elbow_right1" axis="0 -1 1" class="elbow"/>
          <geom name="lower_arm_right1" fromto=".01 .01 .01 .17 .17 .17" class="arm_lower"/>
          <body name="hand_right1" pos=".18 .18 .18">
            <geom name="hand_right1" zaxis="1 1 1" class="hand"/>
          </body>
        </body>
      </body>
      <body name="upper_arm_left1" pos="0 .17 .06">
        <joint name="shoulder1_left1" axis="-2 1 -1" class="shoulder"/>
        <joint name="shoulder2_left1" axis="0 -1 -1" class="shoulder"/>
        <geom name="upper_arm_left1" fromto="0 0 0 .16 .16 -.16" class="arm_upper"/>
        <body name="lower_arm_left1" pos=".18 .18 -.18">
          <joint name="elbow_left1" axis="0 -1 -1" class="elbow"/>
          <geom name="lower_arm_left1" fromto=".01 -.01 .01 .17 -.17 .17" class="arm_lower"/>
          <body name="hand_left1" pos=".18 -.18 .18">
            <geom name="hand_left1" zaxis="1 -1 1" class="hand"/>
          </body>
        </body>
      </body>
    </body>

    <!-- Humanoid 2 - East position -->
    <body name="humanoid2" pos="0.8 0 1.282" childclass="body">
      <freejoint name="root2"/>
      <geom name="torso2" fromto="0 -.07 0 0 .07 0" size=".07"/>
      <geom name="waist_upper2" fromto="-.01 -.06 -.12 -.01 .06 -.12" size=".06"/>
      <body name="head2" pos="0 0 .19">
        <geom name="head2" type="sphere" size=".09"/>
      </body>
      <body name="waist_lower2" pos="-.01 0 -.26">
        <geom name="waist_lower2" fromto="0 -.06 0 0 .06 0" size=".06"/>
        <joint name="abdomen_z2" pos="0 0 .065" axis="0 0 1" range="-45 45" class="joint_big_stiff"/>
        <joint name="abdomen_y2" pos="0 0 .065" axis="0 1 0" range="-75 30" class="joint_big"/>
        <body name="pelvis2" pos="0 0 -.165">
          <joint name="abdomen_x2" pos="0 0 .1" axis="1 0 0" range="-35 35" class="joint_big"/>
          <geom name="butt2" fromto="-.02 -.07 0 -.02 .07 0" size=".09"/>
          <!-- Legs for humanoid2 -->
          <body name="thigh_right2" pos="0 -.1 -.04">
            <joint name="hip_x_right2" axis="1 0 0" class="hip_x"/>
            <joint name="hip_z_right2" axis="0 0 1" class="hip_z"/>
            <joint name="hip_y_right2" class="hip_y"/>
            <geom name="thigh_right2" fromto="0 0 0 0 .01 -.34" class="thigh"/>
            <body name="shin_right2" pos="0 .01 -.4">
              <joint name="knee_right2" class="knee"/>
              <geom name="shin_right2" class="shin"/>
              <body name="foot_right2" pos="0 0 -.39">
                <joint name="ankle_y_right2" class="ankle_y"/>
                <joint name="ankle_x_right2" class="ankle_x" axis="1 0 .5"/>
                <geom name="foot1_right2" class="foot1"/>
                <geom name="foot2_right2" class="foot2"/>
              </body>
            </body>
          </body>
          <body name="thigh_left2" pos="0 .1 -.04">
            <joint name="hip_x_left2" axis="-1 0 0" class="hip_x"/>
            <joint name="hip_z_left2" axis="0 0 -1" class="hip_z"/>
            <joint name="hip_y_left2" class="hip_y"/>
            <geom name="thigh_left2" fromto="0 0 0 0 -.01 -.34" class="thigh"/>
            <body name="shin_left2" pos="0 -.01 -.4">
              <joint name="knee_left2" class="knee"/>
              <geom name="shin_left2" fromto="0 0 0 0 0 -.3" class="shin"/>
              <body name="foot_left2" pos="0 0 -.39">
                <joint name="ankle_y_left2" class="ankle_y"/>
                <joint name="ankle_x_left2" class="ankle_x" axis="-1 0 -.5"/>
                <geom name="foot1_left2" class="foot1"/>
                <geom name="foot2_left2" class="foot2"/>
              </body>
            </body>
          </body>
        </body>
      </body>
      <!-- Arms for humanoid2 -->
      <body name="upper_arm_right2" pos="0 -.17 .06">
        <joint name="shoulder1_right2" axis="2 1 1" class="shoulder"/>
        <joint name="shoulder2_right2" axis="0 -1 1" class="shoulder"/>
        <geom name="upper_arm_right2" fromto="0 0 0 .16 -.16 -.16" class="arm_upper"/>
        <body name="lower_arm_right2" pos=".18 -.18 -.18">
          <joint name="elbow_right2" axis="0 -1 1" class="elbow"/>
          <geom name="lower_arm_right2" fromto=".01 .01 .01 .17 .17 .17" class="arm_lower"/>
          <body name="hand_right2" pos=".18 .18 .18">
            <geom name="hand_right2" zaxis="1 1 1" class="hand"/>
          </body>
        </body>
      </body>
      <body name="upper_arm_left2" pos="0 .17 .06">
        <joint name="shoulder1_left2" axis="-2 1 -1" class="shoulder"/>
        <joint name="shoulder2_left2" axis="0 -1 -1" class="shoulder"/>
        <geom name="upper_arm_left2" fromto="0 0 0 .16 .16 -.16" class="arm_upper"/>
        <body name="lower_arm_left2" pos=".18 .18 -.18">
          <joint name="elbow_left2" axis="0 -1 -1" class="elbow"/>
          <geom name="lower_arm_left2" fromto=".01 -.01 .01 .17 -.17 .17" class="arm_lower"/>
          <body name="hand_left2" pos=".18 -.18 .18">
            <geom name="hand_left2" zaxis="1 -1 1" class="hand"/>
          </body>
        </body>
      </body>
    </body>

    <!-- Humanoid 3 - South position -->
    <body name="humanoid3" pos="0 -0.8 1.282" childclass="body">
      <freejoint name="root3"/>
      <geom name="torso3" fromto="0 -.07 0 0 .07 0" size=".07"/>
      <geom name="waist_upper3" fromto="-.01 -.06 -.12 -.01 .06 -.12" size=".06"/>
      <body name="head3" pos="0 0 .19">
        <geom name="head3" type="sphere" size=".09"/>
      </body>
      <body name="waist_lower3" pos="-.01 0 -.26">
        <geom name="waist_lower3" fromto="0 -.06 0 0 .06 0" size=".06"/>
        <joint name="abdomen_z3" pos="0 0 .065" axis="0 0 1" range="-45 45" class="joint_big_stiff"/>
        <joint name="abdomen_y3" pos="0 0 .065" axis="0 1 0" range="-75 30" class="joint_big"/>
        <body name="pelvis3" pos="0 0 -.165">
          <joint name="abdomen_x3" pos="0 0 .1" axis="1 0 0" range="-35 35" class="joint_big"/>
          <geom name="butt3" fromto="-.02 -.07 0 -.02 .07 0" size=".09"/>
          <!-- Legs for humanoid3 -->
          <body name="thigh_right3" pos="0 -.1 -.04">
            <joint name="hip_x_right3" axis="1 0 0" class="hip_x"/>
            <joint name="hip_z_right3" axis="0 0 1" class="hip_z"/>
            <joint name="hip_y_right3" class="hip_y"/>
            <geom name="thigh_right3" fromto="0 0 0 0 .01 -.34" class="thigh"/>
            <body name="shin_right3" pos="0 .01 -.4">
              <joint name="knee_right3" class="knee"/>
              <geom name="shin_right3" class="shin"/>
              <body name="foot_right3" pos="0 0 -.39">
                <joint name="ankle_y_right3" class="ankle_y"/>
                <joint name="ankle_x_right3" class="ankle_x" axis="1 0 .5"/>
                <geom name="foot1_right3" class="foot1"/>
                <geom name="foot2_right3" class="foot2"/>
              </body>
            </body>
          </body>
          <body name="thigh_left3" pos="0 .1 -.04">
            <joint name="hip_x_left3" axis="-1 0 0" class="hip_x"/>
            <joint name="hip_z_left3" axis="0 0 -1" class="hip_z"/>
            <joint name="hip_y_left3" class="hip_y"/>
            <geom name="thigh_left3" fromto="0 0 0 0 -.01 -.34" class="thigh"/>
            <body name="shin_left3" pos="0 -.01 -.4">
              <joint name="knee_left3" class="knee"/>
              <geom name="shin_left3" fromto="0 0 0 0 0 -.3" class="shin"/>
              <body name="foot_left3" pos="0 0 -.39">
                <joint name="ankle_y_left3" class="ankle_y"/>
                <joint name="ankle_x_left3" class="ankle_x" axis="-1 0 -.5"/>
                <geom name="foot1_left3" class="foot1"/>
                <geom name="foot2_left3" class="foot2"/>
              </body>
            </body>
          </body>
        </body>
      </body>
      <!-- Arms for humanoid3 -->
      <body name="upper_arm_right3" pos="0 -.17 .06">
        <joint name="shoulder1_right3" axis="2 1 1" class="shoulder"/>
        <joint name="shoulder2_right3" axis="0 -1 1" class="shoulder"/>
        <geom name="upper_arm_right3" fromto="0 0 0 .16 -.16 -.16" class="arm_upper"/>
        <body name="lower_arm_right3" pos=".18 -.18 -.18">
          <joint name="elbow_right3" axis="0 -1 1" class="elbow"/>
          <geom name="lower_arm_right3" fromto=".01 .01 .01 .17 .17 .17" class="arm_lower"/>
          <body name="hand_right3" pos=".18 .18 .18">
            <geom name="hand_right3" zaxis="1 1 1" class="hand"/>
          </body>
        </body>
      </body>
      <body name="upper_arm_left3" pos="0 .17 .06">
        <joint name="shoulder1_left3" axis="-2 1 -1" class="shoulder"/>
        <joint name="shoulder2_left3" axis="0 -1 -1" class="shoulder"/>
        <geom name="upper_arm_left3" fromto="0 0 0 .16 .16 -.16" class="arm_upper"/>
        <body name="lower_arm_left3" pos=".18 .18 -.18">
          <joint name="elbow_left3" axis="0 -1 -1" class="elbow"/>
          <geom name="lower_arm_left3" fromto=".01 -.01 .01 .17 -.17 .17" class="arm_lower"/>
          <body name="hand_left3" pos=".18 -.18 .18">
            <geom name="hand_left3" zaxis="1 -1 1" class="hand"/>
          </body>
        </body>
      </body>
    </body>

    <!-- Humanoid 4 - West position -->
    <body name="humanoid4" pos="-0.8 0 1.282" childclass="body">
      <freejoint name="root4"/>
      <geom name="torso4" fromto="0 -.07 0 0 .07 0" size=".07"/>
      <geom name="waist_upper4" fromto="-.01 -.06 -.12 -.01 .06 -.12" size=".06"/>
      <body name="head4" pos="0 0 .19">
        <geom name="head4" type="sphere" size=".09"/>
      </body>
      <body name="waist_lower4" pos="-.01 0 -.26">
        <geom name="waist_lower4" fromto="0 -.06 0 0 .06 0" size=".06"/>
        <joint name="abdomen_z4" pos="0 0 .065" axis="0 0 1" range="-45 45" class="joint_big_stiff"/>
        <joint name="abdomen_y4" pos="0 0 .065" axis="0 1 0" range="-75 30" class="joint_big"/>
        <body name="pelvis4" pos="0 0 -.165">
          <joint name="abdomen_x4" pos="0 0 .1" axis="1 0 0" range="-35 35" class="joint_big"/>
          <geom name="butt4" fromto="-.02 -.07 0 -.02 .07 0" size=".09"/>
          <!-- Legs for humanoid4 -->
          <body name="thigh_right4" pos="0 -.1 -.04">
            <joint name="hip_x_right4" axis="1 0 0" class="hip_x"/>
            <joint name="hip_z_right4" axis="0 0 1" class="hip_z"/>
            <joint name="hip_y_right4" class="hip_y"/>
            <geom name="thigh_right4" fromto="0 0 0 0 .01 -.34" class="thigh"/>
            <body name="shin_right4" pos="0 .01 -.4">
              <joint name="knee_right4" class="knee"/>
              <geom name="shin_right4" class="shin"/>
              <body name="foot_right4" pos="0 0 -.39">
                <joint name="ankle_y_right4" class="ankle_y"/>
                <joint name="ankle_x_right4" class="ankle_x" axis="1 0 .5"/>
                <geom name="foot1_right4" class="foot1"/>
                <geom name="foot2_right4" class="foot2"/>
              </body>
            </body>
          </body>
          <body name="thigh_left4" pos="0 .1 -.04">
            <joint name="hip_x_left4" axis="-1 0 0" class="hip_x"/>
            <joint name="hip_z_left4" axis="0 0 -1" class="hip_z"/>
            <joint name="hip_y_left4" class="hip_y"/>
            <geom name="thigh_left4" fromto="0 0 0 0 -.01 -.34" class="thigh"/>
            <body name="shin_left4" pos="0 -.01 -.4">
              <joint name="knee_left4" class="knee"/>
              <geom name="shin_left4" fromto="0 0 0 0 0 -.3" class="shin"/>
              <body name="foot_left4" pos="0 0 -.39">
                <joint name="ankle_y_left4" class="ankle_y"/>
                <joint name="ankle_x_left4" class="ankle_x" axis="-1 0 -.5"/>
                <geom name="foot1_left4" class="foot1"/>
                <geom name="foot2_left4" class="foot2"/>
              </body>
            </body>
          </body>
        </body>
      </body>
      <!-- Arms for humanoid4 -->
      <body name="upper_arm_right4" pos="0 -.17 .06">
        <joint name="shoulder1_right4" axis="2 1 1" class="shoulder"/>
        <joint name="shoulder2_right4" axis="0 -1 1" class="shoulder"/>
        <geom name="upper_arm_right4" fromto="0 0 0 .16 -.16 -.16" class="arm_upper"/>
        <body name="lower_arm_right4" pos=".18 -.18 -.18">
          <joint name="elbow_right4" axis="0 -1 1" class="elbow"/>
          <geom name="lower_arm_right4" fromto=".01 .01 .01 .17 .17 .17" class="arm_lower"/>
          <body name="hand_right4" pos=".18 .18 .18">
            <geom name="hand_right4" zaxis="1 1 1" class="hand"/>
          </body>
        </body>
      </body>
      <body name="upper_arm_left4" pos="0 .17 .06">
        <joint name="shoulder1_left4" axis="-2 1 -1" class="shoulder"/>
        <joint name="shoulder2_left4" axis="0 -1 -1" class="shoulder"/>
        <geom name="upper_arm_left4" fromto="0 0 0 .16 .16 -.16" class="arm_upper"/>
        <body name="lower_arm_left4" pos=".18 .18 -.18">
          <joint name="elbow_left4" axis="0 -1 -1" class="elbow"/>
          <geom name="lower_arm_left4" fromto=".01 -.01 .01 .17 -.17 .17" class="arm_lower"/>
          <body name="hand_left4" pos=".18 -.18 .18">
            <geom name="hand_left4" zaxis="1 -1 1" class="hand"/>
          </body>
        </body>
      </body>
    </body>

    <!-- Visual connectors between shoulders -->
    <body name="connector_1_2" pos="0.4 0.4 1.4">
      <geom type="cylinder" fromto="-0.4 0.4 0 0.4 -0.4 0" size="0.02" material="connector"/>
    </body>
    <body name="connector_2_3" pos="0.4 -0.4 1.4">
      <geom type="cylinder" fromto="0.4 0.4 0 -0.4 -0.4 0" size="0.02" material="connector"/>
    </body>
    <body name="connector_3_4" pos="-0.4 -0.4 1.4">
      <geom type="cylinder" fromto="0.4 -0.4 0 -0.4 0.4 0" size="0.02" material="connector"/>
    </body>
    <body name="connector_4_1" pos="-0.4 0.4 1.4">
      <geom type="cylinder" fromto="-0.4 -0.4 0 0.4 0.4 0" size="0.02" material="connector"/>
    </body>
  </worldbody>

  <equality>
    <!-- Weld joints connecting the humanoids at their shoulders -->
    <weld name="weld_1_2" body1="hand_left1" body2="hand_right2" relpose="0 0 0 0 0 0 1" solimp="0.9 0.95 0.001" solref="0.02 1"/>
    <weld name="weld_2_3" body1="hand_left2" body2="hand_right3" relpose="0 0 0 0 0 0 1" solimp="0.9 0.95 0.001" solref="0.02 1"/>
    <weld name="weld_3_4" body1="hand_left3" body2="hand_right4" relpose="0 0 0 0 0 0 1" solimp="0.9 0.95 0.001" solref="0.02 1"/>
    <weld name="weld_4_1" body1="hand_left4" body2="hand_right1" relpose="0 0 0 0 0 0 1" solimp="0.9 0.95 0.001" solref="0.02 1"/>
  </equality>

  <contact>
    <exclude body1="waist_lower1" body2="thigh_right1"/>
    <exclude body1="waist_lower1" body2="thigh_left1"/>
    <exclude body1="waist_lower2" body2="thigh_right2"/>
    <exclude body1="waist_lower2" body2="thigh_left2"/>
    <exclude body1="waist_lower3" body2="thigh_right3"/>
    <exclude body1="waist_lower3" body2="thigh_left3"/>
    <exclude body1="waist_lower4" body2="thigh_right4"/>
    <exclude body1="waist_lower4" body2="thigh_left4"/>
  </contact>

  <actuator>
    <!-- Actuators for all humanoids would go here, but removed for simplicity -->
  </actuator>
</mujoco>